2023-11-08 09:08:51,374:INFO:Error while receiving.
Traceback (most recent call last):
  File "/Users/harish/Downloads/spark-3.4.1-bin-hadoop3/python/lib/py4j-0.10.9.7-src.zip/py4j/clientserver.py", line 511, in send_command
    answer = smart_decode(self.stream.readline()[:-1])
RuntimeError: reentrant call inside <_io.BufferedReader name=5>
2023-11-08 09:08:51,376:INFO:Closing down clientserver connection
2023-11-08 09:08:51,376:ERROR:Exception while sending command.
Traceback (most recent call last):
  File "/Users/harish/Downloads/spark-3.4.1-bin-hadoop3/python/lib/py4j-0.10.9.7-src.zip/py4j/clientserver.py", line 511, in send_command
    answer = smart_decode(self.stream.readline()[:-1])
RuntimeError: reentrant call inside <_io.BufferedReader name=5>

During handling of the above exception, another exception occurred:

Traceback (most recent call last):
  File "/Users/harish/Downloads/spark-3.4.1-bin-hadoop3/python/lib/py4j-0.10.9.7-src.zip/py4j/java_gateway.py", line 1038, in send_command
    response = connection.send_command(command)
  File "/Users/harish/Downloads/spark-3.4.1-bin-hadoop3/python/lib/py4j-0.10.9.7-src.zip/py4j/clientserver.py", line 539, in send_command
    raise Py4JNetworkError(
py4j.protocol.Py4JNetworkError: Error while sending or receiving
2023-11-08 09:08:51,381:INFO:Error while receiving.
Traceback (most recent call last):
  File "/Users/harish/Downloads/spark-3.4.1-bin-hadoop3/python/lib/py4j-0.10.9.7-src.zip/py4j/clientserver.py", line 511, in send_command
    answer = smart_decode(self.stream.readline()[:-1])
  File "/Library/Developer/CommandLineTools/Library/Frameworks/Python3.framework/Versions/3.8/lib/python3.8/socket.py", line 669, in readinto
    return self._sock.recv_into(b)
  File "/Users/harish/Downloads/spark-3.4.1-bin-hadoop3/python/pyspark/context.py", line 377, in signal_handler
    self.cancelAllJobs()
  File "/Users/harish/Downloads/spark-3.4.1-bin-hadoop3/python/pyspark/context.py", line 2255, in cancelAllJobs
    self._jsc.sc().cancelAllJobs()
  File "/Users/harish/Downloads/spark-3.4.1-bin-hadoop3/python/lib/py4j-0.10.9.7-src.zip/py4j/java_gateway.py", line 1322, in __call__
    return_value = get_return_value(
  File "/Users/harish/Downloads/spark-3.4.1-bin-hadoop3/python/pyspark/errors/exceptions/captured.py", line 169, in deco
    return f(*a, **kw)
  File "/Users/harish/Downloads/spark-3.4.1-bin-hadoop3/python/lib/py4j-0.10.9.7-src.zip/py4j/protocol.py", line 334, in get_return_value
    raise Py4JError(
py4j.protocol.Py4JError: An error occurred while calling o14.sc
2023-11-08 09:08:51,390:INFO:Closing down clientserver connection
2023-11-08 09:08:51,390:ERROR:Exception while sending command.
Traceback (most recent call last):
  File "/Users/harish/Downloads/spark-3.4.1-bin-hadoop3/python/lib/py4j-0.10.9.7-src.zip/py4j/clientserver.py", line 511, in send_command
    answer = smart_decode(self.stream.readline()[:-1])
  File "/Library/Developer/CommandLineTools/Library/Frameworks/Python3.framework/Versions/3.8/lib/python3.8/socket.py", line 669, in readinto
    return self._sock.recv_into(b)
  File "/Users/harish/Downloads/spark-3.4.1-bin-hadoop3/python/pyspark/context.py", line 377, in signal_handler
    self.cancelAllJobs()
  File "/Users/harish/Downloads/spark-3.4.1-bin-hadoop3/python/pyspark/context.py", line 2255, in cancelAllJobs
    self._jsc.sc().cancelAllJobs()
  File "/Users/harish/Downloads/spark-3.4.1-bin-hadoop3/python/lib/py4j-0.10.9.7-src.zip/py4j/java_gateway.py", line 1322, in __call__
    return_value = get_return_value(
  File "/Users/harish/Downloads/spark-3.4.1-bin-hadoop3/python/pyspark/errors/exceptions/captured.py", line 169, in deco
    return f(*a, **kw)
  File "/Users/harish/Downloads/spark-3.4.1-bin-hadoop3/python/lib/py4j-0.10.9.7-src.zip/py4j/protocol.py", line 334, in get_return_value
    raise Py4JError(
py4j.protocol.Py4JError: An error occurred while calling o14.sc

During handling of the above exception, another exception occurred:

Traceback (most recent call last):
  File "/Users/harish/Downloads/spark-3.4.1-bin-hadoop3/python/lib/py4j-0.10.9.7-src.zip/py4j/java_gateway.py", line 1038, in send_command
    response = connection.send_command(command)
  File "/Users/harish/Downloads/spark-3.4.1-bin-hadoop3/python/lib/py4j-0.10.9.7-src.zip/py4j/clientserver.py", line 539, in send_command
    raise Py4JNetworkError(
py4j.protocol.Py4JNetworkError: Error while sending or receiving
2023-11-08 09:08:51,391:INFO:Closing down clientserver connection
